File: ENG1014/ENG1011Assignment/Al_T18.txt
Stress (MPa)	Strain
0.0086883	0.000019586
0.010142	0.000020177
0.011595	0.000020768
0.013049	0.000021359
0.014502	0.00002195
0.015956	0.000022541
0.017409	0.000023132
0.018863	0.000023723
0.020316	0.000024314
0.02177	0.000024905
0.023223	0.000025496
0.024677	0.000026087
0.049544	0.000026678
0.40352	0.000027269
2.4305	0.00002786
3.9896	0.000028451
7.1803	0.000029042
8.7498	0.000042956
12.007	0.000097766
13.644	0.00015258
17.067	0.00020739
19.096	0.0002622
22.284	0.00031701
25.256	0.00037182
27.99	0.00042663
30.779	0.00048144
33.752	0.00053625
36.77	0.00060325
39.378	0.00078273
41.566	0.00096222
43.166	0.0011417
45.375	0.0014856
46.462	0.0016204
48.444	0.0018766
50.322	0.0021496
52.126	0.0026127
53.659	0.0029175
55.105	0.0032357
56.552	0.003584
57.998	0.0039323
59.444	0.0042806
60.89	0.0046289
61.632	0.0049772
62.716	0.0053255
63.857	0.0056738
64.997	0.0060221
66.138	0.0063703
67.278	0.0067325
68.419	0.0070942
69.56	0.0074547
70.742	0.0078151
71.987	0.0081755
73.244	0.0085077
74.51	0.0088328
75.628	0.0091477
76.611	0.0094627
77.594	0.0097776
78.578	0.010331
79.561	0.01103
80.055	0.011312
81.292	0.011555
82.426	0.011799
83.037	0.01217
83.191	0.01254
84.545	0.012911
85.899	0.01327
87.128	0.013606
88.293	0.013941
89.459	0.014842
89.933	0.015211
90.348	0.015581
90.796	0.01595
91.411	0.01632
92.026	0.016689
92.64	0.017089
93.255	0.017492
94.305	0.017896
95.411	0.0183
96.518	0.018703
97.236	0.019107
97.556	0.019511
98.059	0.019914
100.37	0.020318
100.99	0.020722
101.62	0.021125
102.24	0.021534
102.87	0.021952
103.57	0.02237
104.34	0.022788
105.11	0.023203
105.88	0.023606
106.85	0.02401
107.97	0.024414
108.84	0.024818
109.15	0.025221
109.46	0.025625
109.77	0.026029
110.7	0.026432
111.58	0.026848
111.64	0.027273
112	0.027699
112.49	0.028124
112.98	0.028549
113.48	0.028974
113.75	0.029391
113.94	0.029783
115.99	0.030175
116.51	0.030567
117.04	0.030959
117.56	0.031351
118.08	0.031905
118.6	0.032472
119.12	0.03305
119.65	0.033635
120.17	0.03422
119.76	0.034806
120.3	0.035219
121	0.035573
121.7	0.035927
122.25	0.03628
122.77	0.036634
123.29	0.03706
123.83	0.037519
124.38	0.037977
124.93	0.038427
125.26	0.038854
125.69	0.03928
126.26	0.039707
126.84	0.040134
127.42	0.04056
128	0.040987
128.47	0.041414
128.86	0.041834
129.26	0.042141
129.65	0.042447
130.05	0.042847
130.45	0.043296
130.84	0.043744
131.24	0.045014
131.7	0.045484
132.17	0.045954
132.65	0.046424
132.87	0.046893
133.34	0.047363
133.81	0.047875
134.28	0.048403
134.75	0.04893
135.22	0.049457
135.69	0.049245
136.16	0.04962
136.63	0.049997
133.5	0.050421
133.69	0.050845
134.31	0.051269
134.93	0.051694
135.55	0.052118
136.17	0.052515
136.79	0.052896
137.41	0.053277
137.8	0.054609
137.93	0.055105
138.05	0.055567
138.46	0.05595
139.04	0.056334
139.63	0.056722
139.69	0.057211
139.49	0.057699
139.63	0.058188
139.85	0.058677
140.06	0.059179
140.28	0.059805
140.49	0.060431
140.71	0.061087
142.17	0.06179
141.9	0.062437
142.02	0.062847
142.31	0.063256
142.45	0.063665
142.53	0.064074
143.9	0.064484
145.06	0.064893
144.92	0.065158
144.78	0.065388
143.67	0.06568
141.75	0.06627
141.76	0.06686
142.14	0.067367
142.52	0.067872
142.9	0.068377
143.28	0.068853
143.67	0.069266
144.13	0.06968
144.59	0.070094
145.05	0.070535
145.51	0.071163
145.97	0.071791
146.43	0.072461
146.89	0.073248
147.36	0.073949
147.5	0.074424
147.33	0.074898
147.17	0.075383
147.13	0.075873
147.08	0.076364
147.04	0.076854
147.24	0.077344
147.54	0.077834
147.83	0.078324
148.13	0.078814
148.43	0.079304
148.72	0.079794
149.02	0.080301
149.32	0.080837
149.62	0.081374
149.91	0.081911
150.21	0.082448
150.26	0.082984
150.29	0.083521
150.33	0.084058
150.36	0.084606
150.4	0.085178
150.5	0.085751
150.7	0.086324
150.91	0.086897
151.11	0.087469
151.32	0.088042
151.52	0.088615
151.73	0.089175
151.93	0.089724
152.14	0.090273
152.32	0.090822
152.45	0.091596
152.59	0.092557
152.72	0.093231
152.85	0.093655
152.86	0.094079
152.79	0.094503
152.72	0.094927
152.66	0.095457
152.59	0.09605
152.56	0.096642
152.56	0.097235
152.55	0.097828
152.55	0.09842
152.54	0.099013
152.54	0.099606
152.54	0.1002
152.48	0.10061
152.07	0.10108
152.04	0.10158
152.62	0.10209
152.85	0.10259
153.08	0.1031
153.3	0.10357
153.53	0.10396
153.76	0.10435
153.99	0.10482
154.26	0.10537
154.56	0.10591
154.85	0.10646
155.06	0.10701
154.93	0.10755
154.81	0.10812
154.68	0.1087
154.56	0.10927
154.43	0.10985
154.31	0.11049
154.18	0.11115
154.06	0.11181
154	0.11246
154.1	0.11312
154.21	0.11371
154.31	0.1142
154.42	0.1147
154.52	0.11519
154.63	0.11569
156.22	0.11618
156.25	0.11668
156.29	0.11714
156.33	0.1176
156.36	0.11809
156.11	0.11869
155.85	0.1193
155.71	0.1199
155.57	0.1205
155.44	0.1211
155.3	0.12171
155.17	0.12231
155.03	0.12291
154.89	0.12348
155.14	0.12397
155.43	0.12446
155.69	0.12495
156.4	0.12527
157.41	0.12556
158.41	0.12584
158.1	0.12624
157.46	0.12664
157.28	0.12705
157.22	0.12746
157.16	0.12826
157.09	0.12914
157.03	0.1296
156.97	0.13005
156.9	0.13053
156.86	0.13111
156.88	0.13168
156.89	0.13225
156.9	0.13283
156.91	0.1334
156.92	0.13397
156.96	0.13454
157.04	0.13512
157.11	0.13569
157.18	0.13626
157.25	0.13683
157.24	0.13741
157.11	0.13798
157.09	0.13855
157.13	0.13913
157.16	0.1397
157.19	0.14028
157.22	0.14086
157.25	0.14143
157.26	0.14206
157.23	0.14276
157.21	0.14346
157.18	0.14416
157.16	0.14476
157.23	0.14535
157.7	0.14595
158.18	0.14654
158.56	0.14714
158.48	0.14773
158.39	0.14738
158.31	0.148
158.22	0.14862
156.48	0.14924
156.7	0.14985
156.93	0.15044
157.23	0.15103
157.53	0.15162
157.84	0.15223
158.11	0.15287
158.13	0.1535
158.14	0.15413
158.16	0.15491
158.18	0.15572
158.19	0.15628
158.21	0.15683
158.23	0.15738
158.24	0.15793
158.26	0.15848
158.27	0.15903
158.29	0.15958
158.3	0.16014
158.32	0.16064
158.33	0.16113
158.35	0.16162
158.36	0.16211
158.38	0.16259
158.45	0.16307
158.63	0.16356
158.81	0.16412
159	0.16473
159.09	0.16533
159.06	0.16593
159.03	0.16654
159.01	0.16714
158.98	0.16775
158.96	0.16835
158.94	0.16895
158.93	0.16955
158.92	0.17014
158.9	0.17074
158.89	0.17133
158.88	0.17197
158.87	0.17263
158.87	0.17333
158.87	0.17403
158.86	0.17473
158.86	0.17543
158.86	0.17565
158.86	0.17602
159.01	0.17643
159.15	0.17683
159.29	0.17724
159.43	0.17887
159.58	0.17948
159.3	0.18009
158.87	0.18069
158.66	0.1813
158.44	0.18191
158.51	0.18252
159.21	0.18313
159.51	0.18374
159.39	0.18432
159.26	0.18487
159.14	0.18543
159.02	0.18598
158.9	0.18574
158.85	0.18692
158.79	0.18767
158.74	0.18827
158.69	0.18887
158.64	0.18947
158.59	0.19007
158.54	0.19053
158.49	0.19093
158.44	0.19133
158.38	0.19174
158.33	0.19226
158.28	0.1929
158.23	0.19353
158.18	0.19416
158.13	0.19479
158.08	0.19552
156.87	0.19629
156.81	0.1969
157.29	0.19747
157.29	0.19805
157.3	0.19862
157.3	0.19919
157.33	0.19976
157.46	0.20036
157.59	0.20111
155.29	0.20185
155.36	0.2026
155.42	0.20334
155.46	0.20409
155.36	0.20441
155.26	0.20486
155.13	0.20534
155	0.20582
154.86	0.20631
154.72	0.20683
154.58	0.20746
154.44	0.20808
154.18	0.2087
153.9	0.20933
153.62	0.20995
153.34	0.21058
153.06	0.2112
152.78	0.21183
152.5	0.21245
152.22	0.21307
151.93	0.2137
151.65	0.21432
151.72	0.21496
151.81	0.21566
149.31	0.21635
149.13	0.21705
148.96	0.21775
148.67	0.21845
148.19	0.21914
147.71	0.21984
147.23	0.22054
146.75	0.22124
146.27	0.222
145.47	0.22281
144.67	0.22362
143.87	0.22443
143.07	0.22507
142.4	0.22555
141.72	0.22603
141.05	0.22669
140.38	0.22739
139.7	0.2281
139.03	0.2288
138.36	0.2295
137.68	0.23021
137.01	0.23091
136.33	0.23165
135.63	0.23241
134.75	0.23317
133.87	0.23392
132.99	0.23468
132.11	0.23544
131.23	0.23631
130.29	0.23734
129.12	0.2381
127.94	0.23875
126.76	0.23941
125.59	0.24018
124.41	0.24102
121.99	0.24187
120.06	0.24271
118.42	0.24355
116.77	0.24464
114.9	0.24543
112.72	0.24606
110.54	0.24711
108.36	0.24816